<?xml version="1.0"?>

<robot xmlns:xacro="http://www.ros.org/wiki/xacro" name="moborobo_robot">

  <xacro:property name="mesh_path" value="file://$(find moborobo_robot)/meshes/moborobo_short.stl"/>

  <link name="base_link">
    <visual>
      <geometry>
        <mesh filename="${mesh_path}" scale="1 1 1"/>
      </geometry>
    </visual>
    <collision>
      <origin xyz="0 0 0.04" rpy="0 0 0"/>
      <geometry>
        <box size="0.70 0.470 0.3"/>
      </geometry>
    </collision>
    <inertial>
      <origin xyz="0 0 0.06" rpy="0 0 0"/>
      <mass value="20.0"/>
      <inertia ixx="0.51816" ixy="0" ixz="0" iyy="0.966664" iyz="0" izz="1.18484"/>
    </inertial>
  </link>

  <link name="base_footprint"/>
  <joint name="base_footprint_joint" type="fixed">
    <parent link="base_footprint"/>
    <child link="base_link"/>
    <origin xyz="0 0 0.120" rpy="0 0 0"/>
  </joint>

  <xacro:macro name="caster_wheel" params="caster_name caster_xyz wheel_xyz">
    <link name="${caster_name}">
      <visual>
        <geometry>
          <box size="0.05 0.05 0.05"/>
        </geometry>
        <material name="green">
          <color rgba="0.0 0.1 0.0 1"/>
        </material>
      </visual>
      <collision>
        <geometry>
          <box size="0.05 0.05 0.05"/>
        </geometry>
      </collision>
      <inertial>
        <mass value="0.5"/>
        <inertia ixx="0.000208332" ixy="0" ixz="0" iyy="0.000208332" iyz="0" izz="0.000208332"/>
      </inertial>
    </link>

    <joint name="${caster_name}_joint" type="continuous">
      <parent link="base_link"/>
      <child link="${caster_name}"/>
      <origin xyz="${caster_xyz}" rpy="0 0 0"/>
      <axis xyz="0 0 1"/>
    </joint>

    <link name="${caster_name}_wheel">
      <visual>
        <geometry>
          <cylinder radius="0.04" length="0.0228"/>
        </geometry>
      </visual>
      <collision>
        <geometry>
          <cylinder radius="0.04" length="0.0228"/>
        </geometry>
      </collision>
      <inertial>
        <mass value="0.5"/>
        <inertia ixx="0.00022166" ixy="0" ixz="0" iyy="0.00022166" iyz="0" izz="0.0004"/>
      </inertial>
    </link>

    <joint name="${caster_name}_wheel_joint" type="continuous">
      <parent link="${caster_name}"/>
      <child link="${caster_name}_wheel"/>
      <origin xyz="${wheel_xyz}" rpy="-1.5708 0 0"/>
      <axis xyz="0 0 1"/>
    </joint>
  </xacro:macro>

  <xacro:caster_wheel caster_name="back_left_caster" caster_xyz="-0.300 0.150 -0.130" wheel_xyz="0.02 0 -0.05"/>
  <xacro:caster_wheel caster_name="back_right_caster" caster_xyz="-0.300 -0.150 -0.130" wheel_xyz="0.02 0 -0.05"/>
  <xacro:caster_wheel caster_name="front_left_caster" caster_xyz="0.300 0.150 -0.130" wheel_xyz="0.02 0 -0.05"/>
  <xacro:caster_wheel caster_name="front_right_caster" caster_xyz="0.300 -0.150 -0.130" wheel_xyz="0.02 0 -0.05"/>

  <link name="right_wheel">
    <visual>
      <geometry>
        <cylinder radius="0.1" length="0.04"/>
      </geometry>
    </visual>
    <collision>
      <geometry>
        <cylinder radius="0.1" length="0.04"/>
      </geometry>
    </collision>
    <inertial>
      <mass value="2"/>
      <inertia ixx="0.005066668" ixy="0" ixz="0" iyy="0.005066668" iyz="0" izz="0.01"/>
    </inertial>
  </link>

  <joint name="right_wheel_joint" type="continuous">
    <parent link="base_link"/>
    <child link="right_wheel"/>
    <origin xyz="0.0 -0.175 -0.120" rpy="-1.5708 0 0"/>
    <axis xyz="0 0 1"/>
  </joint>

  <link name="left_wheel">
    <visual>
      <geometry>
        <cylinder radius="0.1" length="0.04"/>
      </geometry>
    </visual>
    <collision>
      <geometry>
        <cylinder radius="0.1" length="0.04"/>
      </geometry>
    </collision>
    <inertial>
      <mass value="0.5"/>
      <inertia ixx="0.001266667" ixy="0" ixz="0" iyy="0.001266667" iyz="0" izz="0.0025"/>
    </inertial>
  </link>

  <joint name="left_wheel_joint" type="continuous">
    <parent link="base_link"/>
    <child link="left_wheel"/>
    <origin xyz="0.0 0.175 -0.120" rpy="-1.5708 0 0"/>
    <axis xyz="0 0 1"/>
  </joint>

  <gazebo>
    <plugin name="gazebo_ros_joint_state_publisher" filename="libgazebo_ros_joint_state_publisher.so">
      <update_rate>50</update_rate>
      <joint_name>front_left_caster_joint</joint_name>
      <joint_name>front_left_caster_wheel_joint</joint_name>
      <joint_name>front_right_caster_joint</joint_name>
      <joint_name>front_right_caster_wheel_joint</joint_name>
      <joint_name>back_left_caster_joint</joint_name>
      <joint_name>back_left_caster_wheel_joint</joint_name>
      <joint_name>back_right_caster_joint</joint_name>
      <joint_name>back_right_caster_wheel_joint</joint_name>
      <joint_name>left_wheel_joint</joint_name>
      <joint_name>right_wheel_joint</joint_name>
    </plugin>
  </gazebo> 

  <gazebo>
    <plugin name="gazebo_ros_p3d" filename="libgazebo_ros_p3d.so">
      <ros>
        <remapping>odom:=ground_truth/odom</remapping>
      </ros>
      <body_name>base_link</body_name>
      <frame_name>world</frame_name>
      <update_rate>50</update_rate>
      <xyz_offsets>0 0 0</xyz_offsets>
      <rpy_offsets>0 0 0</rpy_offsets>
    </plugin>
  </gazebo>

  <!-- Gazebo materials -->
  <gazebo reference="back_left_caster"><material>Gazebo/White</material></gazebo>
  <gazebo reference="back_left_caster_wheel"><material>Gazebo/Black</material></gazebo>
  <gazebo reference="back_right_caster"><material>Gazebo/White</material></gazebo>
  <gazebo reference="back_right_caster_wheel"><material>Gazebo/Black</material></gazebo>
  <gazebo reference="front_left_caster"><material>Gazebo/White</material></gazebo>
  <gazebo reference="front_left_caster_wheel"><material>Gazebo/Black</material></gazebo>
  <gazebo reference="front_right_caster"><material>Gazebo/White</material></gazebo>
  <gazebo reference="front_right_caster_wheel"><material>Gazebo/Black</material></gazebo>
  <gazebo reference="left_wheel"><material>Gazebo/Black</material></gazebo>
  <gazebo reference="right_wheel"><material>Gazebo/Black</material></gazebo>

</robot>